Workbook

Sheet Overview
B2: CAPAR — Guarded Personal First-Order Markov Model
B3: Peserta 4 (peserta4@gmail.com) — user_id 6a7e4feca6e8c17678a91e92
B5: Sumber logika model: | C5: capar.markov.js — PersonalMarkovModel (Dirichlet smoothing, guarded FSM transitions)
B7: Parameter | C7: Nilai | D7: Catatan
B8: Jumlah episode dianalisis | C8: 4 | D8: episode_id 0–3
B9: Jumlah window (baris episodeanalyses) | C9: 240 | D9: seluruh window dari 4 episode
B10: Dirichlet smoothing alpha | C10: 0.5 | D10: sesuai default di capar.markov.js
B11: Window quality gate | C11: quality_gate_pass = 1 | D11: window dengan quality_gate_pass = 0 diabaikan (sesuai w.quality_ok === false di JS)
B12: Status verified episode | C12: diasumsikan verified | D12: dataset test tidak memiliki field verified/status level-episode; seluruh 4 episode disertakan
B14: Daftar sheet:
B15: Episode Windows | C15: Seluruh window mentah (state per 2-menit) untuk Peserta 4, sumber untuk semua perhitungan
B16: Transition Counts | C16: Matriks jumlah transisi valid antar state (formula COUNTIFS dari Episode Windows)
B17: Transition Matrix | C17: Matriks probabilitas P(S_t+1=j | S_t=i) dengan Dirichlet smoothing
B18: Predictions | C18: Prediksi multi-step (+1, +3, +6 window) dari state terakhir Peserta 4 via P^h

Sheet Episode Windows
A1: episode_id | B1: seq | C1: start_time | D1: end_time | E1: raw_state (physiological_state) | F1: quality_gate_pass | G1: included (quality_ok) | H1: norm_state | I1: next_norm_state (same episode) | J1: transition_valid
A2: 0 | B2: 0 | C2: 2026-01-01T08:00:00 | D2: 2026-01-01T08:02:00 | E2: BASELINE_COMPATIBLE | F2: 1 | G2: =IF(F2=0,0,1) -> 1 | H2: =IF(E2="RECOVERY","RECOVERY_START",E2) -> BASELINE_COMPATIBLE | I2: =H3 -> BASELINE_COMPATIBLE | J2: =IF(AND(G2=1,G3=1),1,0) -> 1
A3: 0 | B3: 1 | C3: 2026-01-01T08:02:00 | D3: 2026-01-01T08:04:00 | E3: BASELINE_COMPATIBLE | F3: 1 | G3: =IF(F3=0,0,1) -> 1 | H3: =IF(E3="RECOVERY","RECOVERY_START",E3) -> BASELINE_COMPATIBLE | I3: =H4 -> BASELINE_COMPATIBLE | J3: =IF(AND(G3=1,G4=1),1,0) -> 1
A4: 0 | B4: 2 | C4: 2026-01-01T08:04:00 | D4: 2026-01-01T08:06:00 | E4: BASELINE_COMPATIBLE | F4: 1 | G4: =IF(F4=0,0,1) -> 1 | H4: =IF(E4="RECOVERY","RECOVERY_START",E4) -> BASELINE_COMPATIBLE | I4: =H5 -> BASELINE_COMPATIBLE | J4: =IF(AND(G4=1,G5=1),1,0) -> 1
A5: 0 | B5: 3 | C5: 2026-01-01T08:06:00 | D5: 2026-01-01T08:08:00 | E5: BASELINE_COMPATIBLE | F5: 1 | G5: =IF(F5=0,0,1) -> 1 | H5: =IF(E5="RECOVERY","RECOVERY_START",E5) -> BASELINE_COMPATIBLE | I5: =H6 -> BASELINE_COMPATIBLE | J5: =IF(AND(G5=1,G6=1),1,0) -> 1
A6: 0 | B6: 4 | C6: 2026-01-01T08:08:00 | D6: 2026-01-01T08:10:00 | E6: BASELINE_COMPATIBLE | F6: 1 | G6: =IF(F6=0,0,1) -> 1 | H6: =IF(E6="RECOVERY","RECOVERY_START",E6) -> BASELINE_COMPATIBLE | I6: =H7 -> BASELINE_COMPATIBLE | J6: =IF(AND(G6=1,G7=1),1,0) -> 1
A7: 0 | B7: 5 | C7: 2026-01-01T08:10:00 | D7: 2026-01-01T08:12:00 | E7: BASELINE_COMPATIBLE | F7: 1 | G7: =IF(F7=0,0,1) -> 1 | H7: =IF(E7="RECOVERY","RECOVERY_START",E7) -> BASELINE_COMPATIBLE | I7: =H8 -> BASELINE_COMPATIBLE | J7: =IF(AND(G7=1,G8=1),1,0) -> 1
A8: 0 | B8: 6 | C8: 2026-01-01T08:12:00 | D8: 2026-01-01T08:14:00 | E8: BASELINE_COMPATIBLE | F8: 1 | G8: =IF(F8=0,0,1) -> 1 | H8: =IF(E8="RECOVERY","RECOVERY_START",E8) -> BASELINE_COMPATIBLE | I8: =H9 -> BASELINE_COMPATIBLE | J8: =IF(AND(G8=1,G9=1),1,0) -> 1
A9: 0 | B9: 7 | C9: 2026-01-01T08:14:00 | D9: 2026-01-01T08:16:00 | E9: BASELINE_COMPATIBLE | F9: 1 | G9: =IF(F9=0,0,1) -> 1 | H9: =IF(E9="RECOVERY","RECOVERY_START",E9) -> BASELINE_COMPATIBLE | I9: =H10 -> BASELINE_COMPATIBLE | J9: =IF(AND(G9=1,G10=1),1,0) -> 1
A10: 0 | B10: 8 | C10: 2026-01-01T08:16:00 | D10: 2026-01-01T08:18:00 | E10: BASELINE_COMPATIBLE | F10: 1 | G10: =IF(F10=0,0,1) -> 1 | H10: =IF(E10="RECOVERY","RECOVERY_START",E10) -> BASELINE_COMPATIBLE | I10: =H11 -> BASELINE_COMPATIBLE | J10: =IF(AND(G10=1,G11=1),1,0) -> 1
A11: 0 | B11: 9 | C11: 2026-01-01T08:18:00 | D11: 2026-01-01T08:20:00 | E11: BASELINE_COMPATIBLE | F11: 1 | G11: =IF(F11=0,0,1) -> 1 | H11: =IF(E11="RECOVERY","RECOVERY_START",E11) -> BASELINE_COMPATIBLE | I11: =H12 -> BASELINE_COMPATIBLE | J11: =IF(AND(G11=1,G12=1),1,0) -> 1
A12: 0 | B12: 10 | C12: 2026-01-01T08:20:00 | D12: 2026-01-01T08:22:00 | E12: BASELINE_COMPATIBLE | F12: 1 | G12: =IF(F12=0,0,1) -> 1 | H12: =IF(E12="RECOVERY","RECOVERY_START",E12) -> BASELINE_COMPATIBLE | I12: =H13 -> BASELINE_COMPATIBLE | J12: =IF(AND(G12=1,G13=1),1,0) -> 1
A13: 0 | B13: 11 | C13: 2026-01-01T08:22:00 | D13: 2026-01-01T08:24:00 | E13: BASELINE_COMPATIBLE | F13: 1 | G13: =IF(F13=0,0,1) -> 1 | H13: =IF(E13="RECOVERY","RECOVERY_START",E13) -> BASELINE_COMPATIBLE | I13: =H14 -> BASELINE_COMPATIBLE | J13: =IF(AND(G13=1,G14=1),1,0) -> 1
... A196: 0 | B196: 194 | C196: 2026-01-01T15:56:00 | D196: 2026-01-01T15:58:00 | E196: BASELINE_COMPATIBLE | F196: 1 | G196: =IF(F196=0,0,1) -> 1 | H196: =IF(E196="RECOVERY","RECOVERY_START",E196) -> BASELINE_COMPATIBLE | I196: =H197 -> BASELINE_COMPATIBLE | J196: =IF(AND(G196=1,G197=1),1,0) -> 1
A197: 0 | B197: 195 | C197: 2026-01-01T15:58:00 | D197: 2026-01-01T16:00:00 | E197: BASELINE_COMPATIBLE | F197: 1 | G197: =IF(F197=0,0,1) -> 1 | H197: =IF(E197="RECOVERY","RECOVERY_START",E197) -> BASELINE_COMPATIBLE | J197: 0
A198: 1 | B198: 0 | C198: 2026-01-01T09:00:00 | D198: 2026-01-01T09:02:00 | E198: DEVIATION_CANDIDATE | F198: 1 | G198: =IF(F198=0,0,1) -> 1 | H198: =IF(E198="RECOVERY","RECOVERY_START",E198) -> DEVIATION_CANDIDATE | I198: =H199 -> PERSISTENT_DEVIATION | J198: =IF(AND(G198=1,G199=1),1,0) -> 1
A199: 1 | B199: 1 | C199: 2026-01-01T09:02:00 | D199: 2026-01-01T09:04:00 | E199: PERSISTENT_DEVIATION | F199: 1 | G199: =IF(F199=0,0,1) -> 1 | H199: =IF(E199="RECOVERY","RECOVERY_START",E199) -> PERSISTENT_DEVIATION | I199: =H200 -> PERSISTENT_DEVIATION | J199: =IF(AND(G199=1,G200=1),1,0) -> 1
A200: 1 | B200: 2 | C200: 2026-01-01T09:04:00 | D200: 2026-01-01T09:06:00 | E200: PERSISTENT_DEVIATION | F200: 1 | G200: =IF(F200=0,0,1) -> 1 | H200: =IF(E200="RECOVERY","RECOVERY_START",E200) -> PERSISTENT_DEVIATION | I200: =H201 -> PERSISTENT_DEVIATION | J200: =IF(AND(G200=1,G201=1),1,0) -> 1
A201: 1 | B201: 3 | C201: 2026-01-01T09:06:00 | D201: 2026-01-01T09:08:00 | E201: PERSISTENT_DEVIATION | F201: 1 | G201: =IF(F201=0,0,1) -> 1 | H201: =IF(E201="RECOVERY","RECOVERY_START",E201) -> PERSISTENT_DEVIATION | I201: =H202 -> PERSISTENT_DEVIATION | J201: =IF(AND(G201=1,G202=1),1,0) -> 1
A202: 1 | B202: 4 | C202: 2026-01-01T09:08:00 | D202: 2026-01-01T09:10:00 | E202: PERSISTENT_DEVIATION | F202: 1 | G202: =IF(F202=0,0,1) -> 1 | H202: =IF(E202="RECOVERY","RECOVERY_START",E202) -> PERSISTENT_DEVIATION | I202: =H203 -> PERSISTENT_DEVIATION | J202: =IF(AND(G202=1,G203=1),1,0) -> 1
A203: 1 | B203: 5 | C203: 2026-01-01T09:10:00 | D203: 2026-01-01T09:12:00 | E203: PERSISTENT_DEVIATION | F203: 1 | G203: =IF(F203=0,0,1) -> 1 | H203: =IF(E203="RECOVERY","RECOVERY_START",E203) -> PERSISTENT_DEVIATION | I203: =H204 -> PERSISTENT_DEVIATION | J203: =IF(AND(G203=1,G204=1),1,0) -> 1
A204: 1 | B204: 6 | C204: 2026-01-01T09:12:00 | D204: 2026-01-01T09:14:00 | E204: PERSISTENT_DEVIATION | F204: 1 | G204: =IF(F204=0,0,1) -> 1 | H204: =IF(E204="RECOVERY","RECOVERY_START",E204) -> PERSISTENT_DEVIATION | I204: =H205 -> PERSISTENT_DEVIATION | J204: =IF(AND(G204=1,G205=1),1,0) -> 1
A205: 1 | B205: 7 | C205: 2026-01-01T09:14:00 | D205: 2026-01-01T09:16:00 | E205: PERSISTENT_DEVIATION | F205: 1 | G205: =IF(F205=0,0,1) -> 1 | H205: =IF(E205="RECOVERY","RECOVERY_START",E205) -> PERSISTENT_DEVIATION | I205: =H206 -> PERSISTENT_DEVIATION | J205: =IF(AND(G205=1,G206=1),1,0) -> 1
A206: 1 | B206: 8 | C206: 2026-01-01T09:16:00 | D206: 2026-01-01T09:18:00 | E206: PERSISTENT_DEVIATION | F206: 1 | G206: =IF(F206=0,0,1) -> 1 | H206: =IF(E206="RECOVERY","RECOVERY_START",E206) -> PERSISTENT_DEVIATION | I206: =H207 -> PERSISTENT_DEVIATION | J206: =IF(AND(G206=1,G207=1),1,0) -> 1
A207: 1 | B207: 9 | C207: 2026-01-01T09:18:00 | D207: 2026-01-01T09:20:00 | E207: PERSISTENT_DEVIATION | F207: 1 | G207: =IF(F207=0,0,1) -> 1 | H207: =IF(E207="RECOVERY","RECOVERY_START",E207) -> PERSISTENT_DEVIATION | I207: =H208 -> PERSISTENT_DEVIATION | J207: =IF(AND(G207=1,G208=1),1,0) -> 1
A208: 1 | B208: 10 | C208: 2026-01-01T09:20:00 | D208: 2026-01-01T09:22:00 | E208: PERSISTENT_DEVIATION | F208: 1 | G208: =IF(F208=0,0,1) -> 1 | H208: =IF(E208="RECOVERY","RECOVERY_START",E208) -> PERSISTENT_DEVIATION | I208: =H209 -> RECOVERY_START | J208: =IF(AND(G208=1,G209=1),1,0) -> 1
A209: 1 | B209: 11 | C209: 2026-01-01T09:22:00 | D209: 2026-01-01T09:24:00 | E209: RECOVERY | F209: 1 | G209: =IF(F209=0,0,1) -> 1 | H209: =IF(E209="RECOVERY","RECOVERY_START",E209) -> RECOVERY_START | I209: =H210 -> RECOVERY_START | J209: =IF(AND(G209=1,G210=1),1,0) -> 1
A210: 1 | B210: 12 | C210: 2026-01-01T09:24:00 | D210: 2026-01-01T09:26:00 | E210: RECOVERY | F210: 1 | G210: =IF(F210=0,0,1) -> 1 | H210: =IF(E210="RECOVERY","RECOVERY_START",E210) -> RECOVERY_START | I210: =H211 -> RECOVERED | J210: =IF(AND(G210=1,G211=1),1,0) -> 1
A211: 1 | B211: 13 | C211: 2026-01-01T09:26:00 | D211: 2026-01-01T09:28:00 | E211: RECOVERED | F211: 1 | G211: =IF(F211=0,0,1) -> 1 | H211: =IF(E211="RECOVERY","RECOVERY_START",E211) -> RECOVERED | J211: 0
A212: 2 | B212: 0 | C212: 2026-01-01T11:36:00 | D212: 2026-01-01T11:38:00 | E212: DEVIATION_CANDIDATE | F212: 1 | G212: =IF(F212=0,0,1) -> 1 | H212: =IF(E212="RECOVERY","RECOVERY_START",E212) -> DEVIATION_CANDIDATE | I212: =H213 -> PERSISTENT_DEVIATION | J212: =IF(AND(G212=1,G213=1),1,0) -> 1
A213: 2 | B213: 1 | C213: 2026-01-01T11:38:00 | D213: 2026-01-01T11:40:00 | E213: PERSISTENT_DEVIATION | F213: 1 | G213: =IF(F213=0,0,1) -> 1 | H213: =IF(E213="RECOVERY","RECOVERY_START",E213) -> PERSISTENT_DEVIATION | I213: =H214 -> PERSISTENT_DEVIATION | J213: =IF(AND(G213=1,G214=1),1,0) -> 1
A214: 2 | B214: 2 | C214: 2026-01-01T11:40:00 | D214: 2026-01-01T11:42:00 | E214: PERSISTENT_DEVIATION | F214: 1 | G214: =IF(F214=0,0,1) -> 1 | H214: =IF(E214="RECOVERY","RECOVERY_START",E214) -> PERSISTENT_DEVIATION | I214: =H215 -> PERSISTENT_DEVIATION | J214: =IF(AND(G214=1,G215=1),1,0) -> 1
A215: 2 | B215: 3 | C215: 2026-01-01T11:42:00 | D215: 2026-01-01T11:44:00 | E215: PERSISTENT_DEVIATION | F215: 1 | G215: =IF(F215=0,0,1) -> 1 | H215: =IF(E215="RECOVERY","RECOVERY_START",E215) -> PERSISTENT_DEVIATION | I215: =H216 -> PERSISTENT_DEVIATION | J215: =IF(AND(G215=1,G216=1),1,0) -> 1
A216: 2 | B216: 4 | C216: 2026-01-01T11:44:00 | D216: 2026-01-01T11:46:00 | E216: PERSISTENT_DEVIATION | F216: 1 | G216: =IF(F216=0,0,1) -> 1 | H216: =IF(E216="RECOVERY","RECOVERY_START",E216) -> PERSISTENT_DEVIATION | I216: =H217 -> PERSISTENT_DEVIATION | J216: =IF(AND(G216=1,G217=1),1,0) -> 1
A217: 2 | B217: 5 | C217: 2026-01-01T11:46:00 | D217: 2026-01-01T11:48:00 | E217: PERSISTENT_DEVIATION | F217: 1 | G217: =IF(F217=0,0,1) -> 1 | H217: =IF(E217="RECOVERY","RECOVERY_START",E217) -> PERSISTENT_DEVIATION | I217: =H218 -> PERSISTENT_DEVIATION | J217: =IF(AND(G217=1,G218=1),1,0) -> 1
A218: 2 | B218: 6 | C218: 2026-01-01T11:48:00 | D218: 2026-01-01T11:50:00 | E218: PERSISTENT_DEVIATION | F218: 1 | G218: =IF(F218=0,0,1) -> 1 | H218: =IF(E218="RECOVERY","RECOVERY_START",E218) -> PERSISTENT_DEVIATION | I218: =H219 -> PERSISTENT_DEVIATION | J218: =IF(AND(G218=1,G219=1),1,0) -> 1
A219: 2 | B219: 7 | C219: 2026-01-01T11:50:00 | D219: 2026-01-01T11:52:00 | E219: PERSISTENT_DEVIATION | F219: 1 | G219: =IF(F219=0,0,1) -> 1 | H219: =IF(E219="RECOVERY","RECOVERY_START",E219) -> PERSISTENT_DEVIATION | I219: =H220 -> PERSISTENT_DEVIATION | J219: =IF(AND(G219=1,G220=1),1,0) -> 1
A220: 2 | B220: 8 | C220: 2026-01-01T11:52:00 | D220: 2026-01-01T11:54:00 | E220: PERSISTENT_DEVIATION | F220: 1 | G220: =IF(F220=0,0,1) -> 1 | H220: =IF(E220="RECOVERY","RECOVERY_START",E220) -> PERSISTENT_DEVIATION | I220: =H221 -> PERSISTENT_DEVIATION | J220: =IF(AND(G220=1,G221=1),1,0) -> 1
A221: 2 | B221: 9 | C221: 2026-01-01T11:54:00 | D221: 2026-01-01T11:56:00 | E221: PERSISTENT_DEVIATION | F221: 1 | G221: =IF(F221=0,0,1) -> 1 | H221: =IF(E221="RECOVERY","RECOVERY_START",E221) -> PERSISTENT_DEVIATION | I221: =H222 -> PERSISTENT_DEVIATION | J221: =IF(AND(G221=1,G222=1),1,0) -> 1
A222: 2 | B222: 10 | C222: 2026-01-01T11:56:00 | D222: 2026-01-01T11:58:00 | E222: PERSISTENT_DEVIATION | F222: 1 | G222: =IF(F222=0,0,1) -> 1 | H222: =IF(E222="RECOVERY","RECOVERY_START",E222) -> PERSISTENT_DEVIATION | I222: =H223 -> PERSISTENT_DEVIATION | J222: =IF(AND(G222=1,G223=1),1,0) -> 1
...

Sheet Transition Counts
A1: Transition Counts — hanya dihitung untuk transisi 2 window berurutan dalam episode yang sama & lolos quality gate (transition_valid=1)
A3: from \ to | B3: BASELINE_COMPATIBLE | C3: DEVIATION_CANDIDATE | D3: PERSISTENT_DEVIATION | E3: RECOVERY_START | F3: RECOVERED
A4: BASELINE_COMPATIBLE | B4: =SUMPRODUCT(('Episode Windows'!$H$2:$H$241="BASELINE_COMPATIBLE")*('Episode Windows'!$I$2:$I$241="BASELINE_COMPATIBLE")*('Episode Windows'!$J$2:$J$241=1)) -> 183 | C4: =SUMPRODUCT(('Episode Windows'!$H$2:$H$241="BASELINE_COMPATIBLE")*('Episode Windows'!$I$2:$I$241="DEVIATION_CANDIDATE")*('Episode Windows'!$J$2:$J$241=1)) -> 0 | D4: =SUMPRODUCT(('Episode Windows'!$H$2:$H$241="BASELINE_COMPATIBLE")*('Episode Windows'!$I$2:$I$241="PERSISTENT_DEVIATION")*('Episode Windows'!$J$2:$J$241=1)) -> 0 | E4: =SUMPRODUCT(('Episode Windows'!$H$2:$H$241="BASELINE_COMPATIBLE")*('Episode Windows'!$I$2:$I$241="RECOVERY_START")*('Episode Windows'!$J$2:$J$241=1)) -> 0 | F4: =SUMPRODUCT(('Episode Windows'!$H$2:$H$241="BASELINE_COMPATIBLE")*('Episode Windows'!$I$2:$I$241="RECOVERED")*('Episode Windows'!$J$2:$J$241=1)) -> 0
A5: DEVIATION_CANDIDATE | B5: =SUMPRODUCT(('Episode Windows'!$H$2:$H$241="DEVIATION_CANDIDATE")*('Episode Windows'!$I$2:$I$241="BASELINE_COMPATIBLE")*('Episode Windows'!$J$2:$J$241=1)) -> 0 | C5: =SUMPRODUCT(('Episode Windows'!$H$2:$H$241="DEVIATION_CANDIDATE")*('Episode Windows'!$I$2:$I$241="DEVIATION_CANDIDATE")*('Episode Windows'!$J$2:$J$241=1)) -> 0 | D5: =SUMPRODUCT(('Episode Windows'!$H$2:$H$241="DEVIATION_CANDIDATE")*('Episode Windows'!$I$2:$I$241="PERSISTENT_DEVIATION")*('Episode Windows'!$J$2:$J$241=1)) -> 3 | E5: =SUMPRODUCT(('Episode Windows'!$H$2:$H$241="DEVIATION_CANDIDATE")*('Episode Windows'!$I$2:$I$241="RECOVERY_START")*('Episode Windows'!$J$2:$J$241=1)) -> 0 | F5: =SUMPRODUCT(('Episode Windows'!$H$2:$H$241="DEVIATION_CANDIDATE")*('Episode Windows'!$I$2:$I$241="RECOVERED")*('Episode Windows'!$J$2:$J$241=1)) -> 0
A6: PERSISTENT_DEVIATION | B6: =SUMPRODUCT(('Episode Windows'!$H$2:$H$241="PERSISTENT_DEVIATION")*('Episode Windows'!$I$2:$I$241="BASELINE_COMPATIBLE")*('Episode Windows'!$J$2:$J$241=1)) -> 0 | C6: =SUMPRODUCT(('Episode Windows'!$H$2:$H$241="PERSISTENT_DEVIATION")*('Episode Windows'!$I$2:$I$241="DEVIATION_CANDIDATE")*('Episode Windows'!$J$2:$J$241=1)) -> 0 | D6: =SUMPRODUCT(('Episode Windows'!$H$2:$H$241="PERSISTENT_DEVIATION")*('Episode Windows'!$I$2:$I$241="PERSISTENT_DEVIATION")*('Episode Windows'!$J$2:$J$241=1)) -> 29 | E6: =SUMPRODUCT(('Episode Windows'!$H$2:$H$241="PERSISTENT_DEVIATION")*('Episode Windows'!$I$2:$I$241="RECOVERY_START")*('Episode Windows'!$J$2:$J$241=1)) -> 3 | F6: =SUMPRODUCT(('Episode Windows'!$H$2:$H$241="PERSISTENT_DEVIATION")*('Episode Windows'!$I$2:$I$241="RECOVERED")*('Episode Windows'!$J$2:$J$241=1)) -> 0
A7: RECOVERY_START | B7: =SUMPRODUCT(('Episode Windows'!$H$2:$H$241="RECOVERY_START")*('Episode Windows'!$I$2:$I$241="BASELINE_COMPATIBLE")*('Episode Windows'!$J$2:$J$241=1)) -> 0 | C7: =SUMPRODUCT(('Episode Windows'!$H$2:$H$241="RECOVERY_START")*('Episode Windows'!$I$2:$I$241="DEVIATION_CANDIDATE")*('Episode Windows'!$J$2:$J$241=1)) -> 0 | D7: =SUMPRODUCT(('Episode Windows'!$H$2:$H$241="RECOVERY_START")*('Episode Windows'!$I$2:$I$241="PERSISTENT_DEVIATION")*('Episode Windows'!$J$2:$J$241=1)) -> 0 | E7: =SUMPRODUCT(('Episode Windows'!$H$2:$H$241="RECOVERY_START")*('Episode Windows'!$I$2:$I$241="RECOVERY_START")*('Episode Windows'!$J$2:$J$241=1)) -> 3 | F7: =SUMPRODUCT(('Episode Windows'!$H$2:$H$241="RECOVERY_START")*('Episode Windows'!$I$2:$I$241="RECOVERED")*('Episode Windows'!$J$2:$J$241=1)) -> 3
A8: RECOVERED | B8: =SUMPRODUCT(('Episode Windows'!$H$2:$H$241="RECOVERED")*('Episode Windows'!$I$2:$I$241="BASELINE_COMPATIBLE")*('Episode Windows'!$J$2:$J$241=1)) -> 0 | C8: =SUMPRODUCT(('Episode Windows'!$H$2:$H$241="RECOVERED")*('Episode Windows'!$I$2:$I$241="DEVIATION_CANDIDATE")*('Episode Windows'!$J$2:$J$241=1)) -> 0 | D8: =SUMPRODUCT(('Episode Windows'!$H$2:$H$241="RECOVERED")*('Episode Windows'!$I$2:$I$241="PERSISTENT_DEVIATION")*('Episode Windows'!$J$2:$J$241=1)) -> 0 | E8: =SUMPRODUCT(('Episode Windows'!$H$2:$H$241="RECOVERED")*('Episode Windows'!$I$2:$I$241="RECOVERY_START")*('Episode Windows'!$J$2:$J$241=1)) -> 0 | F8: =SUMPRODUCT(('Episode Windows'!$H$2:$H$241="RECOVERED")*('Episode Windows'!$I$2:$I$241="RECOVERED")*('Episode Windows'!$J$2:$J$241=1)) -> 0
A10: Catatan: total baris (denominator) dihitung langsung di sheet 'Transition Matrix'.
A11: (disusun per kolom state di bawah judul state masing2) | B11: =B4+C4 -> 183 | C11: =B5+C5+D5 -> 3 | D11: =D6+E6 -> 32 | E11: =D7+E7+F7 -> 6 | F11: =B8+F8 -> 0

Sheet Transition Matrix
A1: Transition probability matrix P(S_t+1=j | S_t=i) — Dirichlet smoothing alpha = 0.5. '—' = transisi dilarang FSM (probability = null).
B2: alpha = | C2: 0.5
I3: Numeric matrix (0 menggantikan '—', dipakai untuk MMULT / P^h)
A4: from \ to | B4: BASELINE_COMPATIBLE | C4: DEVIATION_CANDIDATE | D4: PERSISTENT_DEVIATION | E4: RECOVERY_START | F4: RECOVERED | I4: from \ to | J4: BASELINE_COMPATIBLE | K4: DEVIATION_CANDIDATE | L4: PERSISTENT_DEVIATION | M4: RECOVERY_START | N4: RECOVERED
A5: BASELINE_COMPATIBLE | B5: =('Transition Counts'!B4+0.5)/(('Transition Counts'!B4+'Transition Counts'!C4)+0.5*2) -> 0.99728261 | C5: =('Transition Counts'!C4+0.5)/(('Transition Counts'!B4+'Transition Counts'!C4)+0.5*2) -> 0.0027173913 | D5: — | E5: — | F5: — | I5: BASELINE_COMPATIBLE | J5: =IF(ISNUMBER(B5),B5,0) -> 0.99728261 | K5: =IF(ISNUMBER(C5),C5,0) -> 0.0027173913 | L5: =IF(ISNUMBER(D5),D5,0) -> 0 | M5: =IF(ISNUMBER(E5),E5,0) -> 0 | N5: =IF(ISNUMBER(F5),F5,0) -> 0
A6: DEVIATION_CANDIDATE | B6: =('Transition Counts'!B5+0.5)/(('Transition Counts'!B5+'Transition Counts'!C5+'Transition Counts'!D5)+0.5*3) -> 0.11111111 | C6: =('Transition Counts'!C5+0.5)/(('Transition Counts'!B5+'Transition Counts'!C5+'Transition Counts'!D5)+0.5*3) -> 0.11111111 | D6: =('Transition Counts'!D5+0.5)/(('Transition Counts'!B5+'Transition Counts'!C5+'Transition Counts'!D5)+0.5*3) -> 0.77777778 | E6: — | F6: — | I6: DEVIATION_CANDIDATE | J6: =IF(ISNUMBER(B6),B6,0) -> 0.11111111 | K6: =IF(ISNUMBER(C6),C6,0) -> 0.11111111 | L6: =IF(ISNUMBER(D6),D6,0) -> 0.77777778 | M6: =IF(ISNUMBER(E6),E6,0) -> 0 | N6: =IF(ISNUMBER(F6),F6,0) -> 0
A7: PERSISTENT_DEVIATION | B7: — | C7: — | D7: =('Transition Counts'!D6+0.5)/(('Transition Counts'!D6+'Transition Counts'!E6)+0.5*2) -> 0.89393939 | E7: =('Transition Counts'!E6+0.5)/(('Transition Counts'!D6+'Transition Counts'!E6)+0.5*2) -> 0.10606061 | F7: — | I7: PERSISTENT_DEVIATION | J7: =IF(ISNUMBER(B7),B7,0) -> 0 | K7: =IF(ISNUMBER(C7),C7,0) -> 0 | L7: =IF(ISNUMBER(D7),D7,0) -> 0.89393939 | M7: =IF(ISNUMBER(E7),E7,0) -> 0.10606061 | N7: =IF(ISNUMBER(F7),F7,0) -> 0
A8: RECOVERY_START | B8: — | C8: — | D8: =('Transition Counts'!D7+0.5)/(('Transition Counts'!D7+'Transition Counts'!E7+'Transition Counts'!F7)+0.5*3) -> 0.066666667 | E8: =('Transition Counts'!E7+0.5)/(('Transition Counts'!D7+'Transition Counts'!E7+'Transition Counts'!F7)+0.5*3) -> 0.46666667 | F8: =('Transition Counts'!F7+0.5)/(('Transition Counts'!D7+'Transition Counts'!E7+'Transition Counts'!F7)+0.5*3) -> 0.46666667 | I8: RECOVERY_START | J8: =IF(ISNUMBER(B8),B8,0) -> 0 | K8: =IF(ISNUMBER(C8),C8,0) -> 0 | L8: =IF(ISNUMBER(D8),D8,0) -> 0.066666667 | M8: =IF(ISNUMBER(E8),E8,0) -> 0.46666667 | N8: =IF(ISNUMBER(F8),F8,0) -> 0.46666667
A9: RECOVERED | B9: =('Transition Counts'!B8+0.5)/(('Transition Counts'!B8+'Transition Counts'!F8)+0.5*2) -> 0.5 | C9: — | D9: — | E9: — | F9: =('Transition Counts'!F8+0.5)/(('Transition Counts'!B8+'Transition Counts'!F8)+0.5*2) -> 0.5 | I9: RECOVERED | J9: =IF(ISNUMBER(B9),B9,0) -> 0.5 | K9: =IF(ISNUMBER(C9),C9,0) -> 0 | L9: =IF(ISNUMBER(D9),D9,0) -> 0 | M9: =IF(ISNUMBER(E9),E9,0) -> 0 | N9: =IF(ISNUMBER(F9),F9,0) -> 0.5

Sheet Predictions
A1: Multi-step prediction (+h window) — P(S_(t+h)=j | S_t=i) dihitung via P^h (matrix power), sesuai predict() di capar.markov.js
A3: Current state Peserta 4 (window terakhir): | C3: ='Episode Windows'!H241 -> RECOVERED
A4: Waktu window terakhir (end_time): | C4: ='Episode Windows'!D241 -> 2026-01-01T14:36:00
A6: Current state vector (one-hot): | B6: BASELINE_COMPATIBLE | C6: DEVIATION_CANDIDATE | D6: PERSISTENT_DEVIATION | E6: RECOVERY_START | F6: RECOVERED
B7: =IF($C$3="BASELINE_COMPATIBLE",1,0) -> 0 | C7: =IF($C$3="DEVIATION_CANDIDATE",1,0) -> 0 | D7: =IF($C$3="PERSISTENT_DEVIATION",1,0) -> 0 | E7: =IF($C$3="RECOVERY_START",1,0) -> 0 | F7: =IF($C$3="RECOVERED",1,0) -> 1
A9: P^1 (= transition matrix, satu langkah / +1 window)
B10: BASELINE_COMPATIBLE | C10: DEVIATION_CANDIDATE | D10: PERSISTENT_DEVIATION | E10: RECOVERY_START | F10: RECOVERED
A11: BASELINE_COMPATIBLE | B11: {='Transition Matrix'!$J$5:$N$9} -> 0.99728261 | C11: 0.0027173913 | D11: 0 | E11: 0 | F11: 0
A12: DEVIATION_CANDIDATE | B12: 0.11111111 | C12: 0.11111111 | D12: 0.77777778 | E12: 0 | F12: 0
A13: PERSISTENT_DEVIATION | B13: 0 | C13: 0 | D13: 0.89393939 | E13: 0.10606061 | F13: 0
A14: RECOVERY_START | B14: 0 | C14: 0 | D14: 0.066666667 | E14: 0.46666667 | F14: 0.46666667
A15: RECOVERED | B15: 0.5 | C15: 0 | D15: 0 | E15: 0 | F15: 0.5
A17: P^2 (dua langkah / +2 window)
B18: BASELINE_COMPATIBLE | C18: DEVIATION_CANDIDATE | D18: PERSISTENT_DEVIATION | E18: RECOVERY_START | F18: RECOVERED
A19: BASELINE_COMPATIBLE | B19: {=MMULT('Transition Matrix'!$J$5:$N$9,'Transition Matrix'!$J$5:$N$9)} -> 0.99487453 | C19: 0.0030119395 | D19: 0.0021135266 | E19: 0 | F19: 0
A20: DEVIATION_CANDIDATE | B20: 0.12315486 | C20: 0.012647611 | D20: 0.78170595 | E20: 0.082491582 | F20: 0
A21: PERSISTENT_DEVIATION | B21: 0 | C21: 0 | D21: 0.80619835 | E21: 0.1443067 | F21: 0.049494949
A22: RECOVERY_START | B22: 0.23333333 | C22: 0 | D22: 0.090707071 | E22: 0.22484848 | F22: 0.45111111
A23: RECOVERED | B23: 0.7486413 | C23: 0.0013586957 | D23: 0 | E23: 0 | F23: 0.25
A25: P^3 (tiga langkah / +3 window, ~6 menit)
B26: BASELINE_COMPATIBLE | C26: DEVIATION_CANDIDATE | D26: PERSISTENT_DEVIATION | E26: RECOVERY_START | F26: RECOVERED
A27: BASELINE_COMPATIBLE | B27: {=MMULT($B$19:$F$23,'Transition Matrix'!$J$5:$N$9)} -> 0.99250573 | C27: 0.0030381233 | D27: 0.0042319842 | E27: 0.00022416191 | F27: 0
A28: DEVIATION_CANDIDATE | B28: 0.12422549 | C28: 0.0017399501 | D28: 0.71413421 | E28: 0.12140428 | F28: 0.038496072
A29: PERSISTENT_DEVIATION | B29: 0.024747475 | C29: 0 | D29: 0.73031291 | E29: 0.15284901 | F29: 0.092090603
A30: RECOVERY_START | B30: 0.45825483 | C30: 0.00063405797 | D30: 0.096076523 | E30: 0.11454974 | F30: 0.33048485
A31: RECOVERED | B31: 0.87175792 | C31: 0.0021853176 | D31: 0.0010567633 | E31: 0 | F31: 0.125
A33: P^6 (enam langkah / +6 window, ~12 menit)
B34: BASELINE_COMPATIBLE | C34: DEVIATION_CANDIDATE | D34: PERSISTENT_DEVIATION | E34: RECOVERY_START | F34: RECOVERED
A35: BASELINE_COMPATIBLE | B35: {=MMULT($B$27:$F$31,$B$27:$F$31)} -> 0.98565249 | C35: 0.0030207831 | D35: 0.0094821058 | E35: 0.0012638555 | F35: 0.00058076391
A36: DEVIATION_CANDIDATE | B36: 0.23037703 | C36: 0.00054154327 | D36: 0.53501449 | E36: 0.12330062 | F36: 0.11076631
A37: PERSISTENT_DEVIATION | B37: 0.19295992 | C37: 0.00037334823 | D37: 0.5482442 | E37: 0.12914197 | F37: 0.12928056
A38: RECOVERY_START | B38: 0.79787272 | C38: 0.0021881834 | D38: 0.083912839 | E38: 0.027986545 | F38: 0.088039713
A39: RECOVERED | B39: 0.97449209 | C39: 0.0029254751 | D39: 0.0061537391 | E39: 0.00062224705 | F39: 0.015806444
A42: Ringkasan prediksi horizon (dari state saat ini, vector @ P^h)
A43: Horizon (h) | B43: ~Durasi | H43: BASELINE_COMPATIBLE | I43: DEVIATION_CANDIDATE | J43: PERSISTENT_DEVIATION | K43: RECOVERY_START | L43: RECOVERED | M43: Predicted state | N43: Confidence
A44: 1 | B44: ~2 menit | H44: =B$7*B$11+C$7*B$12+D$7*B$13+E$7*B$14+F$7*B$15 -> 0.5 | I44: =B$7*C$11+C$7*C$12+D$7*C$13+E$7*C$14+F$7*C$15 -> 0 | J44: =B$7*D$11+C$7*D$12+D$7*D$13+E$7*D$14+F$7*D$15 -> 0 | K44: =B$7*E$11+C$7*E$12+D$7*E$13+E$7*E$14+F$7*E$15 -> 0 | L44: =B$7*F$11+C$7*F$12+D$7*F$13+E$7*F$14+F$7*F$15 -> 0.5 | M44: =INDEX($B$10:$F$10,MATCH(MAX(H44:L44),H44:L44,0)) -> BASELINE_COMPATIBLE | N44: =MAX(H44:L44) -> 0.5
A45: 3 | B45: ~6 menit | H45: =B$7*B$27+C$7*B$28+D$7*B$29+E$7*B$30+F$7*B$31 -> 0.87175792 | I45: =B$7*C$27+C$7*C$28+D$7*C$29+E$7*C$30+F$7*C$31 -> 0.0021853176 | J45: =B$7*D$27+C$7*D$28+D$7*D$29+E$7*D$30+F$7*D$31 -> 0.0010567633 | K45: =B$7*E$27+C$7*E$28+D$7*E$29+E$7*E$30+F$7*E$31 -> 0 | L45: =B$7*F$27+C$7*F$28+D$7*F$29+E$7*F$30+F$7*F$31 -> 0.125 | M45: =INDEX($B$10:$F$10,MATCH(MAX(H45:L45),H45:L45,0)) -> BASELINE_COMPATIBLE | N45: =MAX(H45:L45) -> 0.87175792
A46: 6 | B46: ~12 menit | H46: =B$7*B$35+C$7*B$36+D$7*B$37+E$7*B$38+F$7*B$39 -> 0.97449209 | I46: =B$7*C$35+C$7*C$36+D$7*C$37+E$7*C$38+F$7*C$39 -> 0.0029254751 | J46: =B$7*D$35+C$7*D$36+D$7*D$37+E$7*D$38+F$7*D$39 -> 0.0061537391 | K46: =B$7*E$35+C$7*E$36+D$7*E$37+E$7*E$38+F$7*E$39 -> 0.00062224705 | L46: =B$7*F$35+C$7*F$36+D$7*F$37+E$7*F$38+F$7*F$39 -> 0.015806444 | M46: =INDEX($B$10:$F$10,MATCH(MAX(H46:L46),H46:L46,0)) -> BASELINE_COMPATIBLE | N46: =MAX(H46:L46) -> 0.97449209
